[2023-02-04 18:43:34,476] {taskinstance.py:1035} INFO - Dependencies all met for <TaskInstance: Train.Train manual__2023-02-04T18:43:31.622861+00:00 [queued]>
[2023-02-04 18:43:34,483] {taskinstance.py:1035} INFO - Dependencies all met for <TaskInstance: Train.Train manual__2023-02-04T18:43:31.622861+00:00 [queued]>
[2023-02-04 18:43:34,483] {taskinstance.py:1241} INFO - 
--------------------------------------------------------------------------------
[2023-02-04 18:43:34,483] {taskinstance.py:1242} INFO - Starting attempt 1 of 1
[2023-02-04 18:43:34,483] {taskinstance.py:1243} INFO - 
--------------------------------------------------------------------------------
[2023-02-04 18:43:34,492] {taskinstance.py:1262} INFO - Executing <Task(BashOperator): Train> on 2023-02-04 18:43:31.622861+00:00
[2023-02-04 18:43:34,493] {standard_task_runner.py:52} INFO - Started process 67130 to run task
[2023-02-04 18:43:34,496] {standard_task_runner.py:76} INFO - Running: ['airflow', 'tasks', 'run', 'Train', 'Train', 'manual__2023-02-04T18:43:31.622861+00:00', '--job-id', '11', '--raw', '--subdir', '/opt/ml/git/final-project-level3-recsys-02/Airflow/dags/RecSys_02.py', '--cfg-path', '/tmp/tmpytmn_uk7', '--error-file', '/tmp/tmpdeggsnj8']
[2023-02-04 18:43:34,497] {standard_task_runner.py:77} INFO - Job 11: Subtask Train
[2023-02-04 18:43:34,520] {logging_mixin.py:109} INFO - Running <TaskInstance: Train.Train manual__2023-02-04T18:43:31.622861+00:00 [running]> on host 3ab801c1e2ef
[2023-02-04 18:43:34,544] {taskinstance.py:1412} INFO - Exporting the following env vars:
AIRFLOW_CTX_DAG_OWNER=RecSys-02
AIRFLOW_CTX_DAG_ID=Train
AIRFLOW_CTX_TASK_ID=Train
AIRFLOW_CTX_EXECUTION_DATE=2023-02-04T18:43:31.622861+00:00
AIRFLOW_CTX_DAG_RUN_ID=manual__2023-02-04T18:43:31.622861+00:00
[2023-02-04 18:43:34,544] {subprocess.py:62} INFO - Tmp dir root location: 
 /tmp
[2023-02-04 18:43:34,545] {subprocess.py:74} INFO - Running command: ['bash', '-c', 'python /opt/ml/git/final-project-level3-recsys-02/bentoml/run_finetune_full.py']
[2023-02-04 18:43:34,550] {subprocess.py:85} INFO - Output:
[2023-02-04 18:43:36,500] {subprocess.py:89} INFO - output/ created
[2023-02-04 18:43:36,501] {subprocess.py:89} INFO - Traceback (most recent call last):
[2023-02-04 18:43:36,501] {subprocess.py:89} INFO -   File "/opt/ml/git/final-project-level3-recsys-02/bentoml/run_finetune_full.py", line 187, in <module>
[2023-02-04 18:43:36,501] {subprocess.py:89} INFO -     main()
[2023-02-04 18:43:36,501] {subprocess.py:89} INFO -   File "/opt/ml/git/final-project-level3-recsys-02/bentoml/run_finetune_full.py", line 100, in main
[2023-02-04 18:43:36,501] {subprocess.py:89} INFO -     item2attribute, attribute_size = get_item2attribute_json(item2attribute_file)
[2023-02-04 18:43:36,501] {subprocess.py:89} INFO -   File "/opt/ml/git/final-project-level3-recsys-02/bentoml/utils.py", line 246, in get_item2attribute_json
[2023-02-04 18:43:36,501] {subprocess.py:89} INFO -     item2attribute = json.loads(open(data_file).readline())  # json file read
[2023-02-04 18:43:36,501] {subprocess.py:89} INFO - FileNotFoundError: [Errno 2] No such file or directory: '_item2attributes.json'
[2023-02-04 18:43:36,693] {subprocess.py:93} INFO - Command exited with return code 1
[2023-02-04 18:43:36,694] {taskinstance.py:1686} ERROR - Task failed with exception
Traceback (most recent call last):
  File "/opt/ml/.cache/pypoetry/virtualenvs/01-bentoml-kzmRLtjI-py3.8/lib/python3.8/site-packages/airflow/models/taskinstance.py", line 1324, in _run_raw_task
    self._execute_task_with_callbacks(context)
  File "/opt/ml/.cache/pypoetry/virtualenvs/01-bentoml-kzmRLtjI-py3.8/lib/python3.8/site-packages/airflow/models/taskinstance.py", line 1443, in _execute_task_with_callbacks
    result = self._execute_task(context, self.task)
  File "/opt/ml/.cache/pypoetry/virtualenvs/01-bentoml-kzmRLtjI-py3.8/lib/python3.8/site-packages/airflow/models/taskinstance.py", line 1499, in _execute_task
    result = execute_callable(context=context)
  File "/opt/ml/.cache/pypoetry/virtualenvs/01-bentoml-kzmRLtjI-py3.8/lib/python3.8/site-packages/airflow/operators/bash.py", line 187, in execute
    raise AirflowException(
airflow.exceptions.AirflowException: Bash command failed. The command returned a non-zero exit code 1.
[2023-02-04 18:43:36,702] {taskinstance.py:1270} INFO - Marking task as FAILED. dag_id=Train, task_id=Train, execution_date=20230204T184331, start_date=20230204T184334, end_date=20230204T184336
[2023-02-04 18:43:36,712] {standard_task_runner.py:88} ERROR - Failed to execute job 11 for task Train
Traceback (most recent call last):
  File "/opt/ml/.cache/pypoetry/virtualenvs/01-bentoml-kzmRLtjI-py3.8/lib/python3.8/site-packages/airflow/task/task_runner/standard_task_runner.py", line 85, in _start_by_fork
    args.func(args, dag=self.dag)
  File "/opt/ml/.cache/pypoetry/virtualenvs/01-bentoml-kzmRLtjI-py3.8/lib/python3.8/site-packages/airflow/cli/cli_parser.py", line 48, in command
    return func(*args, **kwargs)
  File "/opt/ml/.cache/pypoetry/virtualenvs/01-bentoml-kzmRLtjI-py3.8/lib/python3.8/site-packages/airflow/utils/cli.py", line 92, in wrapper
    return f(*args, **kwargs)
  File "/opt/ml/.cache/pypoetry/virtualenvs/01-bentoml-kzmRLtjI-py3.8/lib/python3.8/site-packages/airflow/cli/commands/task_command.py", line 292, in task_run
    _run_task_by_selected_method(args, dag, ti)
  File "/opt/ml/.cache/pypoetry/virtualenvs/01-bentoml-kzmRLtjI-py3.8/lib/python3.8/site-packages/airflow/cli/commands/task_command.py", line 107, in _run_task_by_selected_method
    _run_raw_task(args, ti)
  File "/opt/ml/.cache/pypoetry/virtualenvs/01-bentoml-kzmRLtjI-py3.8/lib/python3.8/site-packages/airflow/cli/commands/task_command.py", line 180, in _run_raw_task
    ti._run_raw_task(
  File "/opt/ml/.cache/pypoetry/virtualenvs/01-bentoml-kzmRLtjI-py3.8/lib/python3.8/site-packages/airflow/utils/session.py", line 70, in wrapper
    return func(*args, session=session, **kwargs)
  File "/opt/ml/.cache/pypoetry/virtualenvs/01-bentoml-kzmRLtjI-py3.8/lib/python3.8/site-packages/airflow/models/taskinstance.py", line 1324, in _run_raw_task
    self._execute_task_with_callbacks(context)
  File "/opt/ml/.cache/pypoetry/virtualenvs/01-bentoml-kzmRLtjI-py3.8/lib/python3.8/site-packages/airflow/models/taskinstance.py", line 1443, in _execute_task_with_callbacks
    result = self._execute_task(context, self.task)
  File "/opt/ml/.cache/pypoetry/virtualenvs/01-bentoml-kzmRLtjI-py3.8/lib/python3.8/site-packages/airflow/models/taskinstance.py", line 1499, in _execute_task
    result = execute_callable(context=context)
  File "/opt/ml/.cache/pypoetry/virtualenvs/01-bentoml-kzmRLtjI-py3.8/lib/python3.8/site-packages/airflow/operators/bash.py", line 187, in execute
    raise AirflowException(
airflow.exceptions.AirflowException: Bash command failed. The command returned a non-zero exit code 1.
[2023-02-04 18:43:36,752] {local_task_job.py:154} INFO - Task exited with return code 1
[2023-02-04 18:43:36,774] {local_task_job.py:264} INFO - 0 downstream tasks scheduled from follow-on schedule check
